2025-03-12 16:48:07-ERROR [log:248] Internal Server Error: /map/
Traceback (most recent call last):
  File "C:\Users\Archi\PycharmProjects\EPC_Map\.venv\Lib\site-packages\django\core\handlers\exception.py", line 55, in inner
    response = get_response(request)
               ^^^^^^^^^^^^^^^^^^^^^
  File "C:\Users\Archi\PycharmProjects\EPC_Map\.venv\Lib\site-packages\django\core\handlers\base.py", line 197, in _get_response
    response = wrapped_callback(request, *callback_args, **callback_kwargs)
               ^^^^^^^^^^^^^^^^^^^^^^^^^^^^^^^^^^^^^^^^^^^^^^^^^^^^^^^^^^^^
  File "C:\Users\Archi\PycharmProjects\EPC_Map\.venv\Lib\site-packages\django\views\generic\base.py", line 104, in view
    return self.dispatch(request, *args, **kwargs)
           ^^^^^^^^^^^^^^^^^^^^^^^^^^^^^^^^^^^^^^^
  File "C:\Users\Archi\PycharmProjects\EPC_Map\.venv\Lib\site-packages\django\views\generic\base.py", line 143, in dispatch
    return handler(request, *args, **kwargs)
           ^^^^^^^^^^^^^^^^^^^^^^^^^^^^^^^^^
  File "C:\Users\Archi\PycharmProjects\EPC_Map\.venv\Lib\site-packages\django\views\generic\base.py", line 227, in get
    return self.render_to_response(context)
           ^^^^^^^^^^^^^^^^^^^^^^^^^^^^^^^^
  File "C:\Users\Archi\PycharmProjects\EPC_Map\.venv\Lib\site-packages\django\views\generic\base.py", line 200, in render_to_response
    template=self.get_template_names(),
             ^^^^^^^^^^^^^^^^^^^^^^^^^
  File "C:\Users\Archi\PycharmProjects\EPC_Map\.venv\Lib\site-packages\django\views\generic\base.py", line 212, in get_template_names
    raise ImproperlyConfigured(
django.core.exceptions.ImproperlyConfigured: TemplateResponseMixin requires either a definition of 'template_name' or an implementation of 'get_template_names()'
2025-03-12 16:52:31-ERROR [log:248] Internal Server Error: /map/
Traceback (most recent call last):
  File "C:\Users\Archi\PycharmProjects\EPC_Map\.venv\Lib\site-packages\django\core\handlers\exception.py", line 55, in inner
    response = get_response(request)
               ^^^^^^^^^^^^^^^^^^^^^
  File "C:\Users\Archi\PycharmProjects\EPC_Map\.venv\Lib\site-packages\django\core\handlers\base.py", line 197, in _get_response
    response = wrapped_callback(request, *callback_args, **callback_kwargs)
               ^^^^^^^^^^^^^^^^^^^^^^^^^^^^^^^^^^^^^^^^^^^^^^^^^^^^^^^^^^^^
  File "C:\Users\Archi\PycharmProjects\EPC_Map\.venv\Lib\site-packages\django\views\generic\base.py", line 104, in view
    return self.dispatch(request, *args, **kwargs)
           ^^^^^^^^^^^^^^^^^^^^^^^^^^^^^^^^^^^^^^^
  File "C:\Users\Archi\PycharmProjects\EPC_Map\.venv\Lib\site-packages\django\views\generic\base.py", line 143, in dispatch
    return handler(request, *args, **kwargs)
           ^^^^^^^^^^^^^^^^^^^^^^^^^^^^^^^^^
  File "C:\Users\Archi\PycharmProjects\EPC_Map\.venv\Lib\site-packages\django\views\generic\base.py", line 227, in get
    return self.render_to_response(context)
           ^^^^^^^^^^^^^^^^^^^^^^^^^^^^^^^^
  File "C:\Users\Archi\PycharmProjects\EPC_Map\.venv\Lib\site-packages\django\views\generic\base.py", line 200, in render_to_response
    template=self.get_template_names(),
             ^^^^^^^^^^^^^^^^^^^^^^^^^
  File "C:\Users\Archi\PycharmProjects\EPC_Map\.venv\Lib\site-packages\django\views\generic\base.py", line 212, in get_template_names
    raise ImproperlyConfigured(
django.core.exceptions.ImproperlyConfigured: TemplateResponseMixin requires either a definition of 'template_name' or an implementation of 'get_template_names()'
2025-03-12 17:01:08-ERROR [log:248] Internal Server Error: /map/
Traceback (most recent call last):
  File "C:\Users\Archi\PycharmProjects\EPC_Map\.venv\Lib\site-packages\django\template\backends\django.py", line 107, in render
    return self.template.render(context)
           ^^^^^^^^^^^^^^^^^^^^^^^^^^^^^
  File "C:\Users\Archi\PycharmProjects\EPC_Map\.venv\Lib\site-packages\django\template\base.py", line 171, in render
    return self._render(context)
           ^^^^^^^^^^^^^^^^^^^^^
  File "C:\Users\Archi\PycharmProjects\EPC_Map\.venv\Lib\site-packages\django\template\base.py", line 163, in _render
    return self.nodelist.render(context)
           ^^^^^^^^^^^^^^^^^^^^^^^^^^^^^
  File "C:\Users\Archi\PycharmProjects\EPC_Map\.venv\Lib\site-packages\django\template\base.py", line 1008, in render
    return SafeString("".join([node.render_annotated(context) for node in self]))
                              ^^^^^^^^^^^^^^^^^^^^^^^^^^^^^^^^^^^^^^^^^^^^^^^^^
  File "C:\Users\Archi\PycharmProjects\EPC_Map\.venv\Lib\site-packages\django\template\base.py", line 1008, in <listcomp>
    return SafeString("".join([node.render_annotated(context) for node in self]))
                               ^^^^^^^^^^^^^^^^^^^^^^^^^^^^^^
  File "C:\Users\Archi\PycharmProjects\EPC_Map\.venv\Lib\site-packages\django\template\base.py", line 969, in render_annotated
    return self.render(context)
           ^^^^^^^^^^^^^^^^^^^^
  File "C:\Users\Archi\PycharmProjects\EPC_Map\.venv\Lib\site-packages\django\template\loader_tags.py", line 159, in render
    return compiled_parent._render(context)
           ^^^^^^^^^^^^^^^^^^^^^^^^^^^^^^^^
  File "C:\Users\Archi\PycharmProjects\EPC_Map\.venv\Lib\site-packages\django\template\base.py", line 163, in _render
    return self.nodelist.render(context)
           ^^^^^^^^^^^^^^^^^^^^^^^^^^^^^
  File "C:\Users\Archi\PycharmProjects\EPC_Map\.venv\Lib\site-packages\django\template\base.py", line 1008, in render
    return SafeString("".join([node.render_annotated(context) for node in self]))
                              ^^^^^^^^^^^^^^^^^^^^^^^^^^^^^^^^^^^^^^^^^^^^^^^^^
  File "C:\Users\Archi\PycharmProjects\EPC_Map\.venv\Lib\site-packages\django\template\base.py", line 1008, in <listcomp>
    return SafeString("".join([node.render_annotated(context) for node in self]))
                               ^^^^^^^^^^^^^^^^^^^^^^^^^^^^^^
  File "C:\Users\Archi\PycharmProjects\EPC_Map\.venv\Lib\site-packages\django\template\base.py", line 969, in render_annotated
    return self.render(context)
           ^^^^^^^^^^^^^^^^^^^^
  File "C:\Users\Archi\PycharmProjects\EPC_Map\.venv\Lib\site-packages\django\template\loader_tags.py", line 65, in render
    result = block.nodelist.render(context)
             ^^^^^^^^^^^^^^^^^^^^^^^^^^^^^^
  File "C:\Users\Archi\PycharmProjects\EPC_Map\.venv\Lib\site-packages\django\template\base.py", line 1008, in render
    return SafeString("".join([node.render_annotated(context) for node in self]))
                              ^^^^^^^^^^^^^^^^^^^^^^^^^^^^^^^^^^^^^^^^^^^^^^^^^
  File "C:\Users\Archi\PycharmProjects\EPC_Map\.venv\Lib\site-packages\django\template\base.py", line 1008, in <listcomp>
    return SafeString("".join([node.render_annotated(context) for node in self]))
                               ^^^^^^^^^^^^^^^^^^^^^^^^^^^^^^
  File "C:\Users\Archi\PycharmProjects\EPC_Map\.venv\Lib\site-packages\django\template\base.py", line 969, in render_annotated
    return self.render(context)
           ^^^^^^^^^^^^^^^^^^^^
  File "C:\Users\Archi\PycharmProjects\EPC_Map\.venv\Lib\site-packages\django\template\loader_tags.py", line 199, in render
    template = context.template.engine.select_template(template_name)
               ^^^^^^^^^^^^^^^^^^^^^^^^^^^^^^^^^^^^^^^^^^^^^^^^^^^^^^
  File "C:\Users\Archi\PycharmProjects\EPC_Map\.venv\Lib\site-packages\django\template\engine.py", line 214, in select_template
    raise TemplateDoesNotExist(", ".join(not_found))
django.template.exceptions.TemplateDoesNotExist: includes/header.html

The above exception was the direct cause of the following exception:

Traceback (most recent call last):
  File "C:\Users\Archi\PycharmProjects\EPC_Map\.venv\Lib\site-packages\django\core\handlers\exception.py", line 55, in inner
    response = get_response(request)
               ^^^^^^^^^^^^^^^^^^^^^
  File "C:\Users\Archi\PycharmProjects\EPC_Map\.venv\Lib\site-packages\django\core\handlers\base.py", line 220, in _get_response
    response = response.render()
               ^^^^^^^^^^^^^^^^^
  File "C:\Users\Archi\PycharmProjects\EPC_Map\.venv\Lib\site-packages\django\template\response.py", line 114, in render
    self.content = self.rendered_content
                   ^^^^^^^^^^^^^^^^^^^^^
  File "C:\Users\Archi\PycharmProjects\EPC_Map\.venv\Lib\site-packages\django\template\response.py", line 92, in rendered_content
    return template.render(context, self._request)
           ^^^^^^^^^^^^^^^^^^^^^^^^^^^^^^^^^^^^^^^
  File "C:\Users\Archi\PycharmProjects\EPC_Map\.venv\Lib\site-packages\django\template\backends\django.py", line 109, in render
    reraise(exc, self.backend)
  File "C:\Users\Archi\PycharmProjects\EPC_Map\.venv\Lib\site-packages\django\template\backends\django.py", line 130, in reraise
    raise new from exc
django.template.exceptions.TemplateDoesNotExist: includes/header.html
2025-03-12 17:01:20-ERROR [log:248] Internal Server Error: /map/
Traceback (most recent call last):
  File "C:\Users\Archi\PycharmProjects\EPC_Map\.venv\Lib\site-packages\django\template\backends\django.py", line 107, in render
    return self.template.render(context)
           ^^^^^^^^^^^^^^^^^^^^^^^^^^^^^
  File "C:\Users\Archi\PycharmProjects\EPC_Map\.venv\Lib\site-packages\django\template\base.py", line 171, in render
    return self._render(context)
           ^^^^^^^^^^^^^^^^^^^^^
  File "C:\Users\Archi\PycharmProjects\EPC_Map\.venv\Lib\site-packages\django\template\base.py", line 163, in _render
    return self.nodelist.render(context)
           ^^^^^^^^^^^^^^^^^^^^^^^^^^^^^
  File "C:\Users\Archi\PycharmProjects\EPC_Map\.venv\Lib\site-packages\django\template\base.py", line 1008, in render
    return SafeString("".join([node.render_annotated(context) for node in self]))
                              ^^^^^^^^^^^^^^^^^^^^^^^^^^^^^^^^^^^^^^^^^^^^^^^^^
  File "C:\Users\Archi\PycharmProjects\EPC_Map\.venv\Lib\site-packages\django\template\base.py", line 1008, in <listcomp>
    return SafeString("".join([node.render_annotated(context) for node in self]))
                               ^^^^^^^^^^^^^^^^^^^^^^^^^^^^^^
  File "C:\Users\Archi\PycharmProjects\EPC_Map\.venv\Lib\site-packages\django\template\base.py", line 969, in render_annotated
    return self.render(context)
           ^^^^^^^^^^^^^^^^^^^^
  File "C:\Users\Archi\PycharmProjects\EPC_Map\.venv\Lib\site-packages\django\template\loader_tags.py", line 159, in render
    return compiled_parent._render(context)
           ^^^^^^^^^^^^^^^^^^^^^^^^^^^^^^^^
  File "C:\Users\Archi\PycharmProjects\EPC_Map\.venv\Lib\site-packages\django\template\base.py", line 163, in _render
    return self.nodelist.render(context)
           ^^^^^^^^^^^^^^^^^^^^^^^^^^^^^
  File "C:\Users\Archi\PycharmProjects\EPC_Map\.venv\Lib\site-packages\django\template\base.py", line 1008, in render
    return SafeString("".join([node.render_annotated(context) for node in self]))
                              ^^^^^^^^^^^^^^^^^^^^^^^^^^^^^^^^^^^^^^^^^^^^^^^^^
  File "C:\Users\Archi\PycharmProjects\EPC_Map\.venv\Lib\site-packages\django\template\base.py", line 1008, in <listcomp>
    return SafeString("".join([node.render_annotated(context) for node in self]))
                               ^^^^^^^^^^^^^^^^^^^^^^^^^^^^^^
  File "C:\Users\Archi\PycharmProjects\EPC_Map\.venv\Lib\site-packages\django\template\base.py", line 969, in render_annotated
    return self.render(context)
           ^^^^^^^^^^^^^^^^^^^^
  File "C:\Users\Archi\PycharmProjects\EPC_Map\.venv\Lib\site-packages\django\template\loader_tags.py", line 65, in render
    result = block.nodelist.render(context)
             ^^^^^^^^^^^^^^^^^^^^^^^^^^^^^^
  File "C:\Users\Archi\PycharmProjects\EPC_Map\.venv\Lib\site-packages\django\template\base.py", line 1008, in render
    return SafeString("".join([node.render_annotated(context) for node in self]))
                              ^^^^^^^^^^^^^^^^^^^^^^^^^^^^^^^^^^^^^^^^^^^^^^^^^
  File "C:\Users\Archi\PycharmProjects\EPC_Map\.venv\Lib\site-packages\django\template\base.py", line 1008, in <listcomp>
    return SafeString("".join([node.render_annotated(context) for node in self]))
                               ^^^^^^^^^^^^^^^^^^^^^^^^^^^^^^
  File "C:\Users\Archi\PycharmProjects\EPC_Map\.venv\Lib\site-packages\django\template\base.py", line 969, in render_annotated
    return self.render(context)
           ^^^^^^^^^^^^^^^^^^^^
  File "C:\Users\Archi\PycharmProjects\EPC_Map\.venv\Lib\site-packages\django\template\loader_tags.py", line 199, in render
    template = context.template.engine.select_template(template_name)
               ^^^^^^^^^^^^^^^^^^^^^^^^^^^^^^^^^^^^^^^^^^^^^^^^^^^^^^
  File "C:\Users\Archi\PycharmProjects\EPC_Map\.venv\Lib\site-packages\django\template\engine.py", line 214, in select_template
    raise TemplateDoesNotExist(", ".join(not_found))
django.template.exceptions.TemplateDoesNotExist: select/filter_select.html

The above exception was the direct cause of the following exception:

Traceback (most recent call last):
  File "C:\Users\Archi\PycharmProjects\EPC_Map\.venv\Lib\site-packages\django\core\handlers\exception.py", line 55, in inner
    response = get_response(request)
               ^^^^^^^^^^^^^^^^^^^^^
  File "C:\Users\Archi\PycharmProjects\EPC_Map\.venv\Lib\site-packages\django\core\handlers\base.py", line 220, in _get_response
    response = response.render()
               ^^^^^^^^^^^^^^^^^
  File "C:\Users\Archi\PycharmProjects\EPC_Map\.venv\Lib\site-packages\django\template\response.py", line 114, in render
    self.content = self.rendered_content
                   ^^^^^^^^^^^^^^^^^^^^^
  File "C:\Users\Archi\PycharmProjects\EPC_Map\.venv\Lib\site-packages\django\template\response.py", line 92, in rendered_content
    return template.render(context, self._request)
           ^^^^^^^^^^^^^^^^^^^^^^^^^^^^^^^^^^^^^^^
  File "C:\Users\Archi\PycharmProjects\EPC_Map\.venv\Lib\site-packages\django\template\backends\django.py", line 109, in render
    reraise(exc, self.backend)
  File "C:\Users\Archi\PycharmProjects\EPC_Map\.venv\Lib\site-packages\django\template\backends\django.py", line 130, in reraise
    raise new from exc
django.template.exceptions.TemplateDoesNotExist: select/filter_select.html
2025-03-12 23:38:29-ERROR [log:248] Internal Server Error: /api/map/
Traceback (most recent call last):
  File "C:\Users\Archi\PycharmProjects\EPC_Map\.venv\Lib\site-packages\rest_framework\fields.py", line 437, in get_attribute
    return get_attribute(instance, self.source_attrs)
           ^^^^^^^^^^^^^^^^^^^^^^^^^^^^^^^^^^^^^^^^^^
  File "C:\Users\Archi\PycharmProjects\EPC_Map\.venv\Lib\site-packages\rest_framework\fields.py", line 104, in get_attribute
    instance = getattr(instance, attr)
               ^^^^^^^^^^^^^^^^^^^^^^^
AttributeError: 'QuerySet' object has no attribute 'lmk_key'

During handling of the above exception, another exception occurred:

Traceback (most recent call last):
  File "C:\Users\Archi\PycharmProjects\EPC_Map\.venv\Lib\site-packages\django\core\handlers\exception.py", line 55, in inner
    response = get_response(request)
               ^^^^^^^^^^^^^^^^^^^^^
  File "C:\Users\Archi\PycharmProjects\EPC_Map\.venv\Lib\site-packages\django\core\handlers\base.py", line 197, in _get_response
    response = wrapped_callback(request, *callback_args, **callback_kwargs)
               ^^^^^^^^^^^^^^^^^^^^^^^^^^^^^^^^^^^^^^^^^^^^^^^^^^^^^^^^^^^^
  File "C:\Users\Archi\PycharmProjects\EPC_Map\.venv\Lib\site-packages\django\views\decorators\csrf.py", line 65, in _view_wrapper
    return view_func(request, *args, **kwargs)
           ^^^^^^^^^^^^^^^^^^^^^^^^^^^^^^^^^^^
  File "C:\Users\Archi\PycharmProjects\EPC_Map\.venv\Lib\site-packages\django\views\generic\base.py", line 104, in view
    return self.dispatch(request, *args, **kwargs)
           ^^^^^^^^^^^^^^^^^^^^^^^^^^^^^^^^^^^^^^^
  File "C:\Users\Archi\PycharmProjects\EPC_Map\.venv\Lib\site-packages\rest_framework\views.py", line 509, in dispatch
    response = self.handle_exception(exc)
               ^^^^^^^^^^^^^^^^^^^^^^^^^^
  File "C:\Users\Archi\PycharmProjects\EPC_Map\.venv\Lib\site-packages\rest_framework\views.py", line 469, in handle_exception
    self.raise_uncaught_exception(exc)
  File "C:\Users\Archi\PycharmProjects\EPC_Map\.venv\Lib\site-packages\rest_framework\views.py", line 480, in raise_uncaught_exception
    raise exc
  File "C:\Users\Archi\PycharmProjects\EPC_Map\.venv\Lib\site-packages\rest_framework\views.py", line 506, in dispatch
    response = handler(request, *args, **kwargs)
               ^^^^^^^^^^^^^^^^^^^^^^^^^^^^^^^^^
  File "C:\Users\Archi\PycharmProjects\EPC_Map\EPC_MAP\map\views.py", line 25, in get
    return JsonResponse(data=serializer.data, status=200)
                             ^^^^^^^^^^^^^^^
  File "C:\Users\Archi\PycharmProjects\EPC_Map\.venv\Lib\site-packages\rest_framework\serializers.py", line 571, in data
    ret = super().data
          ^^^^^^^^^^^^
  File "C:\Users\Archi\PycharmProjects\EPC_Map\.venv\Lib\site-packages\rest_framework\serializers.py", line 249, in data
    self._data = self.to_representation(self.instance)
                 ^^^^^^^^^^^^^^^^^^^^^^^^^^^^^^^^^^^^^
  File "C:\Users\Archi\PycharmProjects\EPC_Map\.venv\Lib\site-packages\rest_framework\serializers.py", line 525, in to_representation
    attribute = field.get_attribute(instance)
                ^^^^^^^^^^^^^^^^^^^^^^^^^^^^^
  File "C:\Users\Archi\PycharmProjects\EPC_Map\.venv\Lib\site-packages\rest_framework\fields.py", line 470, in get_attribute
    raise type(exc)(msg)
AttributeError: Got AttributeError when attempting to get a value for field `lmk_key` on serializer `CertificateSerializer`.
The serializer field might be named incorrectly and not match any attribute or key on the `QuerySet` instance.
Original exception text was: 'QuerySet' object has no attribute 'lmk_key'.
2025-03-12 23:39:35-ERROR [log:248] Internal Server Error: /api/map/
Traceback (most recent call last):
  File "C:\Users\Archi\PycharmProjects\EPC_Map\.venv\Lib\site-packages\rest_framework\fields.py", line 437, in get_attribute
    return get_attribute(instance, self.source_attrs)
           ^^^^^^^^^^^^^^^^^^^^^^^^^^^^^^^^^^^^^^^^^^
  File "C:\Users\Archi\PycharmProjects\EPC_Map\.venv\Lib\site-packages\rest_framework\fields.py", line 104, in get_attribute
    instance = getattr(instance, attr)
               ^^^^^^^^^^^^^^^^^^^^^^^
AttributeError: 'QuerySet' object has no attribute 'lmk_key'

During handling of the above exception, another exception occurred:

Traceback (most recent call last):
  File "C:\Users\Archi\PycharmProjects\EPC_Map\.venv\Lib\site-packages\django\core\handlers\exception.py", line 55, in inner
    response = get_response(request)
               ^^^^^^^^^^^^^^^^^^^^^
  File "C:\Users\Archi\PycharmProjects\EPC_Map\.venv\Lib\site-packages\django\core\handlers\base.py", line 197, in _get_response
    response = wrapped_callback(request, *callback_args, **callback_kwargs)
               ^^^^^^^^^^^^^^^^^^^^^^^^^^^^^^^^^^^^^^^^^^^^^^^^^^^^^^^^^^^^
  File "C:\Users\Archi\PycharmProjects\EPC_Map\.venv\Lib\site-packages\django\views\decorators\csrf.py", line 65, in _view_wrapper
    return view_func(request, *args, **kwargs)
           ^^^^^^^^^^^^^^^^^^^^^^^^^^^^^^^^^^^
  File "C:\Users\Archi\PycharmProjects\EPC_Map\.venv\Lib\site-packages\django\views\generic\base.py", line 104, in view
    return self.dispatch(request, *args, **kwargs)
           ^^^^^^^^^^^^^^^^^^^^^^^^^^^^^^^^^^^^^^^
  File "C:\Users\Archi\PycharmProjects\EPC_Map\.venv\Lib\site-packages\rest_framework\views.py", line 509, in dispatch
    response = self.handle_exception(exc)
               ^^^^^^^^^^^^^^^^^^^^^^^^^^
  File "C:\Users\Archi\PycharmProjects\EPC_Map\.venv\Lib\site-packages\rest_framework\views.py", line 469, in handle_exception
    self.raise_uncaught_exception(exc)
  File "C:\Users\Archi\PycharmProjects\EPC_Map\.venv\Lib\site-packages\rest_framework\views.py", line 480, in raise_uncaught_exception
    raise exc
  File "C:\Users\Archi\PycharmProjects\EPC_Map\.venv\Lib\site-packages\rest_framework\views.py", line 506, in dispatch
    response = handler(request, *args, **kwargs)
               ^^^^^^^^^^^^^^^^^^^^^^^^^^^^^^^^^
  File "C:\Users\Archi\PycharmProjects\EPC_Map\EPC_MAP\map\views.py", line 25, in get
    return JsonResponse(data=serializer.data, status=200)
                             ^^^^^^^^^^^^^^^
  File "C:\Users\Archi\PycharmProjects\EPC_Map\.venv\Lib\site-packages\rest_framework\serializers.py", line 571, in data
    ret = super().data
          ^^^^^^^^^^^^
  File "C:\Users\Archi\PycharmProjects\EPC_Map\.venv\Lib\site-packages\rest_framework\serializers.py", line 249, in data
    self._data = self.to_representation(self.instance)
                 ^^^^^^^^^^^^^^^^^^^^^^^^^^^^^^^^^^^^^
  File "C:\Users\Archi\PycharmProjects\EPC_Map\.venv\Lib\site-packages\rest_framework\serializers.py", line 525, in to_representation
    attribute = field.get_attribute(instance)
                ^^^^^^^^^^^^^^^^^^^^^^^^^^^^^
  File "C:\Users\Archi\PycharmProjects\EPC_Map\.venv\Lib\site-packages\rest_framework\fields.py", line 470, in get_attribute
    raise type(exc)(msg)
AttributeError: Got AttributeError when attempting to get a value for field `lmk_key` on serializer `CertificateSerializer`.
The serializer field might be named incorrectly and not match any attribute or key on the `QuerySet` instance.
Original exception text was: 'QuerySet' object has no attribute 'lmk_key'.
2025-03-12 23:42:44-ERROR [log:248] Internal Server Error: /api/map/
Traceback (most recent call last):
  File "C:\Users\Archi\PycharmProjects\EPC_Map\.venv\Lib\site-packages\django\core\handlers\exception.py", line 55, in inner
    response = get_response(request)
               ^^^^^^^^^^^^^^^^^^^^^
  File "C:\Users\Archi\PycharmProjects\EPC_Map\.venv\Lib\site-packages\django\core\handlers\base.py", line 197, in _get_response
    response = wrapped_callback(request, *callback_args, **callback_kwargs)
               ^^^^^^^^^^^^^^^^^^^^^^^^^^^^^^^^^^^^^^^^^^^^^^^^^^^^^^^^^^^^
  File "C:\Users\Archi\PycharmProjects\EPC_Map\.venv\Lib\site-packages\django\views\decorators\csrf.py", line 65, in _view_wrapper
    return view_func(request, *args, **kwargs)
           ^^^^^^^^^^^^^^^^^^^^^^^^^^^^^^^^^^^
  File "C:\Users\Archi\PycharmProjects\EPC_Map\.venv\Lib\site-packages\django\views\generic\base.py", line 104, in view
    return self.dispatch(request, *args, **kwargs)
           ^^^^^^^^^^^^^^^^^^^^^^^^^^^^^^^^^^^^^^^
  File "C:\Users\Archi\PycharmProjects\EPC_Map\.venv\Lib\site-packages\rest_framework\views.py", line 509, in dispatch
    response = self.handle_exception(exc)
               ^^^^^^^^^^^^^^^^^^^^^^^^^^
  File "C:\Users\Archi\PycharmProjects\EPC_Map\.venv\Lib\site-packages\rest_framework\views.py", line 469, in handle_exception
    self.raise_uncaught_exception(exc)
  File "C:\Users\Archi\PycharmProjects\EPC_Map\.venv\Lib\site-packages\rest_framework\views.py", line 480, in raise_uncaught_exception
    raise exc
  File "C:\Users\Archi\PycharmProjects\EPC_Map\.venv\Lib\site-packages\rest_framework\views.py", line 506, in dispatch
    response = handler(request, *args, **kwargs)
               ^^^^^^^^^^^^^^^^^^^^^^^^^^^^^^^^^
  File "C:\Users\Archi\PycharmProjects\EPC_Map\EPC_MAP\map\views.py", line 24, in get
    return JsonResponse(data=serializer.data, status=200)
           ^^^^^^^^^^^^^^^^^^^^^^^^^^^^^^^^^^^^^^^^^^^^^^
  File "C:\Users\Archi\PycharmProjects\EPC_Map\.venv\Lib\site-packages\django\http\response.py", line 726, in __init__
    raise TypeError(
TypeError: In order to allow non-dict objects to be serialized set the safe parameter to False.
2025-03-12 23:43:03-ERROR [log:248] Internal Server Error: /api/map/
Traceback (most recent call last):
  File "C:\Users\Archi\PycharmProjects\EPC_Map\.venv\Lib\site-packages\django\core\handlers\exception.py", line 55, in inner
    response = get_response(request)
               ^^^^^^^^^^^^^^^^^^^^^
  File "C:\Users\Archi\PycharmProjects\EPC_Map\.venv\Lib\site-packages\django\core\handlers\base.py", line 197, in _get_response
    response = wrapped_callback(request, *callback_args, **callback_kwargs)
               ^^^^^^^^^^^^^^^^^^^^^^^^^^^^^^^^^^^^^^^^^^^^^^^^^^^^^^^^^^^^
  File "C:\Users\Archi\PycharmProjects\EPC_Map\.venv\Lib\site-packages\django\views\decorators\csrf.py", line 65, in _view_wrapper
    return view_func(request, *args, **kwargs)
           ^^^^^^^^^^^^^^^^^^^^^^^^^^^^^^^^^^^
  File "C:\Users\Archi\PycharmProjects\EPC_Map\.venv\Lib\site-packages\django\views\generic\base.py", line 104, in view
    return self.dispatch(request, *args, **kwargs)
           ^^^^^^^^^^^^^^^^^^^^^^^^^^^^^^^^^^^^^^^
  File "C:\Users\Archi\PycharmProjects\EPC_Map\.venv\Lib\site-packages\rest_framework\views.py", line 509, in dispatch
    response = self.handle_exception(exc)
               ^^^^^^^^^^^^^^^^^^^^^^^^^^
  File "C:\Users\Archi\PycharmProjects\EPC_Map\.venv\Lib\site-packages\rest_framework\views.py", line 469, in handle_exception
    self.raise_uncaught_exception(exc)
  File "C:\Users\Archi\PycharmProjects\EPC_Map\.venv\Lib\site-packages\rest_framework\views.py", line 480, in raise_uncaught_exception
    raise exc
  File "C:\Users\Archi\PycharmProjects\EPC_Map\.venv\Lib\site-packages\rest_framework\views.py", line 506, in dispatch
    response = handler(request, *args, **kwargs)
               ^^^^^^^^^^^^^^^^^^^^^^^^^^^^^^^^^
  File "C:\Users\Archi\PycharmProjects\EPC_Map\EPC_MAP\map\views.py", line 24, in get
    return JsonResponse(data=serializer.data, status=200)
           ^^^^^^^^^^^^^^^^^^^^^^^^^^^^^^^^^^^^^^^^^^^^^^
  File "C:\Users\Archi\PycharmProjects\EPC_Map\.venv\Lib\site-packages\django\http\response.py", line 726, in __init__
    raise TypeError(
TypeError: In order to allow non-dict objects to be serialized set the safe parameter to False.
2025-03-12 23:47:27-ERROR [log:248] Internal Server Error: /api/map/
Traceback (most recent call last):
  File "C:\Users\Archi\PycharmProjects\EPC_Map\.venv\Lib\site-packages\django\core\handlers\exception.py", line 55, in inner
    response = get_response(request)
               ^^^^^^^^^^^^^^^^^^^^^
  File "C:\Users\Archi\PycharmProjects\EPC_Map\.venv\Lib\site-packages\django\core\handlers\base.py", line 197, in _get_response
    response = wrapped_callback(request, *callback_args, **callback_kwargs)
               ^^^^^^^^^^^^^^^^^^^^^^^^^^^^^^^^^^^^^^^^^^^^^^^^^^^^^^^^^^^^
  File "C:\Users\Archi\PycharmProjects\EPC_Map\.venv\Lib\site-packages\django\views\decorators\csrf.py", line 65, in _view_wrapper
    return view_func(request, *args, **kwargs)
           ^^^^^^^^^^^^^^^^^^^^^^^^^^^^^^^^^^^
  File "C:\Users\Archi\PycharmProjects\EPC_Map\.venv\Lib\site-packages\django\views\generic\base.py", line 104, in view
    return self.dispatch(request, *args, **kwargs)
           ^^^^^^^^^^^^^^^^^^^^^^^^^^^^^^^^^^^^^^^
  File "C:\Users\Archi\PycharmProjects\EPC_Map\.venv\Lib\site-packages\rest_framework\views.py", line 509, in dispatch
    response = self.handle_exception(exc)
               ^^^^^^^^^^^^^^^^^^^^^^^^^^
  File "C:\Users\Archi\PycharmProjects\EPC_Map\.venv\Lib\site-packages\rest_framework\views.py", line 469, in handle_exception
    self.raise_uncaught_exception(exc)
  File "C:\Users\Archi\PycharmProjects\EPC_Map\.venv\Lib\site-packages\rest_framework\views.py", line 480, in raise_uncaught_exception
    raise exc
  File "C:\Users\Archi\PycharmProjects\EPC_Map\.venv\Lib\site-packages\rest_framework\views.py", line 506, in dispatch
    response = handler(request, *args, **kwargs)
               ^^^^^^^^^^^^^^^^^^^^^^^^^^^^^^^^^
  File "C:\Users\Archi\PycharmProjects\EPC_Map\EPC_MAP\map\views.py", line 20, in get
    return JsonResponse(data=serializer.data, safe=False, status=200)
                             ^^^^^^^^^^^^^^^
  File "C:\Users\Archi\PycharmProjects\EPC_Map\.venv\Lib\site-packages\rest_framework\serializers.py", line 795, in data
    ret = super().data
          ^^^^^^^^^^^^
  File "C:\Users\Archi\PycharmProjects\EPC_Map\.venv\Lib\site-packages\rest_framework\serializers.py", line 249, in data
    self._data = self.to_representation(self.instance)
                 ^^^^^^^^^^^^^^^^^^^^^^^^^^^^^^^^^^^^^
  File "C:\Users\Archi\PycharmProjects\EPC_Map\.venv\Lib\site-packages\rest_framework\serializers.py", line 713, in to_representation
    return [
           ^
  File "C:\Users\Archi\PycharmProjects\EPC_Map\.venv\Lib\site-packages\django\db\models\query.py", line 400, in __iter__
    self._fetch_all()
  File "C:\Users\Archi\PycharmProjects\EPC_Map\.venv\Lib\site-packages\rest_framework\views.py", line 131, in force_evaluation
    raise RuntimeError(
RuntimeError: Do not evaluate the `.queryset` attribute directly, as the result will be cached and reused between requests. Use `.all()` or call `.get_queryset()` instead.
2025-03-12 23:47:53-ERROR [log:248] Internal Server Error: /api/map/
Traceback (most recent call last):
  File "C:\Users\Archi\PycharmProjects\EPC_Map\.venv\Lib\site-packages\django\core\handlers\exception.py", line 55, in inner
    response = get_response(request)
               ^^^^^^^^^^^^^^^^^^^^^
  File "C:\Users\Archi\PycharmProjects\EPC_Map\.venv\Lib\site-packages\django\core\handlers\base.py", line 197, in _get_response
    response = wrapped_callback(request, *callback_args, **callback_kwargs)
               ^^^^^^^^^^^^^^^^^^^^^^^^^^^^^^^^^^^^^^^^^^^^^^^^^^^^^^^^^^^^
  File "C:\Users\Archi\PycharmProjects\EPC_Map\.venv\Lib\site-packages\django\views\decorators\csrf.py", line 65, in _view_wrapper
    return view_func(request, *args, **kwargs)
           ^^^^^^^^^^^^^^^^^^^^^^^^^^^^^^^^^^^
  File "C:\Users\Archi\PycharmProjects\EPC_Map\.venv\Lib\site-packages\django\views\generic\base.py", line 104, in view
    return self.dispatch(request, *args, **kwargs)
           ^^^^^^^^^^^^^^^^^^^^^^^^^^^^^^^^^^^^^^^
  File "C:\Users\Archi\PycharmProjects\EPC_Map\.venv\Lib\site-packages\rest_framework\views.py", line 509, in dispatch
    response = self.handle_exception(exc)
               ^^^^^^^^^^^^^^^^^^^^^^^^^^
  File "C:\Users\Archi\PycharmProjects\EPC_Map\.venv\Lib\site-packages\rest_framework\views.py", line 469, in handle_exception
    self.raise_uncaught_exception(exc)
  File "C:\Users\Archi\PycharmProjects\EPC_Map\.venv\Lib\site-packages\rest_framework\views.py", line 480, in raise_uncaught_exception
    raise exc
  File "C:\Users\Archi\PycharmProjects\EPC_Map\.venv\Lib\site-packages\rest_framework\views.py", line 506, in dispatch
    response = handler(request, *args, **kwargs)
               ^^^^^^^^^^^^^^^^^^^^^^^^^^^^^^^^^
  File "C:\Users\Archi\PycharmProjects\EPC_Map\EPC_MAP\map\views.py", line 20, in get
    return JsonResponse(data=serializer.data, safe=False, status=200)
                             ^^^^^^^^^^^^^^^
  File "C:\Users\Archi\PycharmProjects\EPC_Map\.venv\Lib\site-packages\rest_framework\serializers.py", line 795, in data
    ret = super().data
          ^^^^^^^^^^^^
  File "C:\Users\Archi\PycharmProjects\EPC_Map\.venv\Lib\site-packages\rest_framework\serializers.py", line 249, in data
    self._data = self.to_representation(self.instance)
                 ^^^^^^^^^^^^^^^^^^^^^^^^^^^^^^^^^^^^^
  File "C:\Users\Archi\PycharmProjects\EPC_Map\.venv\Lib\site-packages\rest_framework\serializers.py", line 713, in to_representation
    return [
           ^
  File "C:\Users\Archi\PycharmProjects\EPC_Map\.venv\Lib\site-packages\django\db\models\query.py", line 400, in __iter__
    self._fetch_all()
  File "C:\Users\Archi\PycharmProjects\EPC_Map\.venv\Lib\site-packages\rest_framework\views.py", line 131, in force_evaluation
    raise RuntimeError(
RuntimeError: Do not evaluate the `.queryset` attribute directly, as the result will be cached and reused between requests. Use `.all()` or call `.get_queryset()` instead.
2025-03-12 23:48:21-ERROR [log:248] Internal Server Error: /api/map/
Traceback (most recent call last):
  File "C:\Users\Archi\PycharmProjects\EPC_Map\.venv\Lib\site-packages\django\core\handlers\exception.py", line 55, in inner
    response = get_response(request)
               ^^^^^^^^^^^^^^^^^^^^^
  File "C:\Users\Archi\PycharmProjects\EPC_Map\.venv\Lib\site-packages\django\core\handlers\base.py", line 197, in _get_response
    response = wrapped_callback(request, *callback_args, **callback_kwargs)
               ^^^^^^^^^^^^^^^^^^^^^^^^^^^^^^^^^^^^^^^^^^^^^^^^^^^^^^^^^^^^
  File "C:\Users\Archi\PycharmProjects\EPC_Map\.venv\Lib\site-packages\django\views\decorators\csrf.py", line 65, in _view_wrapper
    return view_func(request, *args, **kwargs)
           ^^^^^^^^^^^^^^^^^^^^^^^^^^^^^^^^^^^
  File "C:\Users\Archi\PycharmProjects\EPC_Map\.venv\Lib\site-packages\django\views\generic\base.py", line 104, in view
    return self.dispatch(request, *args, **kwargs)
           ^^^^^^^^^^^^^^^^^^^^^^^^^^^^^^^^^^^^^^^
  File "C:\Users\Archi\PycharmProjects\EPC_Map\.venv\Lib\site-packages\rest_framework\views.py", line 509, in dispatch
    response = self.handle_exception(exc)
               ^^^^^^^^^^^^^^^^^^^^^^^^^^
  File "C:\Users\Archi\PycharmProjects\EPC_Map\.venv\Lib\site-packages\rest_framework\views.py", line 469, in handle_exception
    self.raise_uncaught_exception(exc)
  File "C:\Users\Archi\PycharmProjects\EPC_Map\.venv\Lib\site-packages\rest_framework\views.py", line 480, in raise_uncaught_exception
    raise exc
  File "C:\Users\Archi\PycharmProjects\EPC_Map\.venv\Lib\site-packages\rest_framework\views.py", line 506, in dispatch
    response = handler(request, *args, **kwargs)
               ^^^^^^^^^^^^^^^^^^^^^^^^^^^^^^^^^
  File "C:\Users\Archi\PycharmProjects\EPC_Map\EPC_MAP\map\views.py", line 23, in get
    return JsonResponse(data=serializer.data, safe=False, status=200)
                             ^^^^^^^^^^^^^^^
  File "C:\Users\Archi\PycharmProjects\EPC_Map\.venv\Lib\site-packages\rest_framework\serializers.py", line 795, in data
    ret = super().data
          ^^^^^^^^^^^^
  File "C:\Users\Archi\PycharmProjects\EPC_Map\.venv\Lib\site-packages\rest_framework\serializers.py", line 249, in data
    self._data = self.to_representation(self.instance)
                 ^^^^^^^^^^^^^^^^^^^^^^^^^^^^^^^^^^^^^
  File "C:\Users\Archi\PycharmProjects\EPC_Map\.venv\Lib\site-packages\rest_framework\serializers.py", line 713, in to_representation
    return [
           ^
  File "C:\Users\Archi\PycharmProjects\EPC_Map\.venv\Lib\site-packages\django\db\models\query.py", line 400, in __iter__
    self._fetch_all()
  File "C:\Users\Archi\PycharmProjects\EPC_Map\.venv\Lib\site-packages\rest_framework\views.py", line 131, in force_evaluation
    raise RuntimeError(
RuntimeError: Do not evaluate the `.queryset` attribute directly, as the result will be cached and reused between requests. Use `.all()` or call `.get_queryset()` instead.
2025-03-12 23:50:21-ERROR [log:248] Internal Server Error: /api/map/
Traceback (most recent call last):
  File "C:\Users\Archi\PycharmProjects\EPC_Map\.venv\Lib\site-packages\django\core\handlers\exception.py", line 55, in inner
    response = get_response(request)
               ^^^^^^^^^^^^^^^^^^^^^
  File "C:\Users\Archi\PycharmProjects\EPC_Map\.venv\Lib\site-packages\django\core\handlers\base.py", line 197, in _get_response
    response = wrapped_callback(request, *callback_args, **callback_kwargs)
               ^^^^^^^^^^^^^^^^^^^^^^^^^^^^^^^^^^^^^^^^^^^^^^^^^^^^^^^^^^^^
  File "C:\Users\Archi\PycharmProjects\EPC_Map\.venv\Lib\site-packages\django\views\decorators\csrf.py", line 65, in _view_wrapper
    return view_func(request, *args, **kwargs)
           ^^^^^^^^^^^^^^^^^^^^^^^^^^^^^^^^^^^
  File "C:\Users\Archi\PycharmProjects\EPC_Map\.venv\Lib\site-packages\django\views\generic\base.py", line 104, in view
    return self.dispatch(request, *args, **kwargs)
           ^^^^^^^^^^^^^^^^^^^^^^^^^^^^^^^^^^^^^^^
  File "C:\Users\Archi\PycharmProjects\EPC_Map\.venv\Lib\site-packages\rest_framework\views.py", line 509, in dispatch
    response = self.handle_exception(exc)
               ^^^^^^^^^^^^^^^^^^^^^^^^^^
  File "C:\Users\Archi\PycharmProjects\EPC_Map\.venv\Lib\site-packages\rest_framework\views.py", line 469, in handle_exception
    self.raise_uncaught_exception(exc)
  File "C:\Users\Archi\PycharmProjects\EPC_Map\.venv\Lib\site-packages\rest_framework\views.py", line 480, in raise_uncaught_exception
    raise exc
  File "C:\Users\Archi\PycharmProjects\EPC_Map\.venv\Lib\site-packages\rest_framework\views.py", line 506, in dispatch
    response = handler(request, *args, **kwargs)
               ^^^^^^^^^^^^^^^^^^^^^^^^^^^^^^^^^
  File "C:\Users\Archi\PycharmProjects\EPC_Map\EPC_MAP\map\views.py", line 21, in get
    queryset = self.get_queryset()
               ^^^^^^^^^^^^^^^^^^^
  File "C:\Users\Archi\PycharmProjects\EPC_Map\EPC_MAP\map\views.py", line 18, in get_queryset
    return Certificate.objects.valu('pk', 'latitude', 'longitude')
           ^^^^^^^^^^^^^^^^^^^^^^^^
AttributeError: 'Manager' object has no attribute 'valu'
2025-03-12 23:50:55-ERROR [log:248] Internal Server Error: /api/map/
Traceback (most recent call last):
  File "C:\Users\Archi\PycharmProjects\EPC_Map\.venv\Lib\site-packages\rest_framework\fields.py", line 437, in get_attribute
    return get_attribute(instance, self.source_attrs)
           ^^^^^^^^^^^^^^^^^^^^^^^^^^^^^^^^^^^^^^^^^^
  File "C:\Users\Archi\PycharmProjects\EPC_Map\.venv\Lib\site-packages\rest_framework\fields.py", line 104, in get_attribute
    instance = getattr(instance, attr)
               ^^^^^^^^^^^^^^^^^^^^^^^
AttributeError: 'tuple' object has no attribute 'lmk_key'

During handling of the above exception, another exception occurred:

Traceback (most recent call last):
  File "C:\Users\Archi\PycharmProjects\EPC_Map\.venv\Lib\site-packages\django\core\handlers\exception.py", line 55, in inner
    response = get_response(request)
               ^^^^^^^^^^^^^^^^^^^^^
  File "C:\Users\Archi\PycharmProjects\EPC_Map\.venv\Lib\site-packages\django\core\handlers\base.py", line 197, in _get_response
    response = wrapped_callback(request, *callback_args, **callback_kwargs)
               ^^^^^^^^^^^^^^^^^^^^^^^^^^^^^^^^^^^^^^^^^^^^^^^^^^^^^^^^^^^^
  File "C:\Users\Archi\PycharmProjects\EPC_Map\.venv\Lib\site-packages\django\views\decorators\csrf.py", line 65, in _view_wrapper
    return view_func(request, *args, **kwargs)
           ^^^^^^^^^^^^^^^^^^^^^^^^^^^^^^^^^^^
  File "C:\Users\Archi\PycharmProjects\EPC_Map\.venv\Lib\site-packages\django\views\generic\base.py", line 104, in view
    return self.dispatch(request, *args, **kwargs)
           ^^^^^^^^^^^^^^^^^^^^^^^^^^^^^^^^^^^^^^^
  File "C:\Users\Archi\PycharmProjects\EPC_Map\.venv\Lib\site-packages\rest_framework\views.py", line 509, in dispatch
    response = self.handle_exception(exc)
               ^^^^^^^^^^^^^^^^^^^^^^^^^^
  File "C:\Users\Archi\PycharmProjects\EPC_Map\.venv\Lib\site-packages\rest_framework\views.py", line 469, in handle_exception
    self.raise_uncaught_exception(exc)
  File "C:\Users\Archi\PycharmProjects\EPC_Map\.venv\Lib\site-packages\rest_framework\views.py", line 480, in raise_uncaught_exception
    raise exc
  File "C:\Users\Archi\PycharmProjects\EPC_Map\.venv\Lib\site-packages\rest_framework\views.py", line 506, in dispatch
    response = handler(request, *args, **kwargs)
               ^^^^^^^^^^^^^^^^^^^^^^^^^^^^^^^^^
  File "C:\Users\Archi\PycharmProjects\EPC_Map\EPC_MAP\map\views.py", line 24, in get
    return JsonResponse(data=serializer.data, safe=False, status=200)
                             ^^^^^^^^^^^^^^^
  File "C:\Users\Archi\PycharmProjects\EPC_Map\.venv\Lib\site-packages\rest_framework\serializers.py", line 795, in data
    ret = super().data
          ^^^^^^^^^^^^
  File "C:\Users\Archi\PycharmProjects\EPC_Map\.venv\Lib\site-packages\rest_framework\serializers.py", line 249, in data
    self._data = self.to_representation(self.instance)
                 ^^^^^^^^^^^^^^^^^^^^^^^^^^^^^^^^^^^^^
  File "C:\Users\Archi\PycharmProjects\EPC_Map\.venv\Lib\site-packages\rest_framework\serializers.py", line 713, in to_representation
    return [
           ^
  File "C:\Users\Archi\PycharmProjects\EPC_Map\.venv\Lib\site-packages\rest_framework\serializers.py", line 714, in <listcomp>
    self.child.to_representation(item) for item in iterable
    ^^^^^^^^^^^^^^^^^^^^^^^^^^^^^^^^^^
  File "C:\Users\Archi\PycharmProjects\EPC_Map\.venv\Lib\site-packages\rest_framework\serializers.py", line 525, in to_representation
    attribute = field.get_attribute(instance)
                ^^^^^^^^^^^^^^^^^^^^^^^^^^^^^
  File "C:\Users\Archi\PycharmProjects\EPC_Map\.venv\Lib\site-packages\rest_framework\fields.py", line 470, in get_attribute
    raise type(exc)(msg)
AttributeError: Got AttributeError when attempting to get a value for field `lmk_key` on serializer `CertificateSerializer`.
The serializer field might be named incorrectly and not match any attribute or key on the `tuple` instance.
Original exception text was: 'tuple' object has no attribute 'lmk_key'.
2025-03-12 23:53:28-ERROR [log:248] Internal Server Error: /api/map/
Traceback (most recent call last):
  File "C:\Users\Archi\PycharmProjects\EPC_Map\.venv\Lib\site-packages\rest_framework\fields.py", line 437, in get_attribute
    return get_attribute(instance, self.source_attrs)
           ^^^^^^^^^^^^^^^^^^^^^^^^^^^^^^^^^^^^^^^^^^
  File "C:\Users\Archi\PycharmProjects\EPC_Map\.venv\Lib\site-packages\rest_framework\fields.py", line 104, in get_attribute
    instance = getattr(instance, attr)
               ^^^^^^^^^^^^^^^^^^^^^^^
AttributeError: 'tuple' object has no attribute 'lmk_key'

During handling of the above exception, another exception occurred:

Traceback (most recent call last):
  File "C:\Users\Archi\PycharmProjects\EPC_Map\.venv\Lib\site-packages\django\core\handlers\exception.py", line 55, in inner
    response = get_response(request)
               ^^^^^^^^^^^^^^^^^^^^^
  File "C:\Users\Archi\PycharmProjects\EPC_Map\.venv\Lib\site-packages\django\core\handlers\base.py", line 197, in _get_response
    response = wrapped_callback(request, *callback_args, **callback_kwargs)
               ^^^^^^^^^^^^^^^^^^^^^^^^^^^^^^^^^^^^^^^^^^^^^^^^^^^^^^^^^^^^
  File "C:\Users\Archi\PycharmProjects\EPC_Map\.venv\Lib\site-packages\django\views\decorators\csrf.py", line 65, in _view_wrapper
    return view_func(request, *args, **kwargs)
           ^^^^^^^^^^^^^^^^^^^^^^^^^^^^^^^^^^^
  File "C:\Users\Archi\PycharmProjects\EPC_Map\.venv\Lib\site-packages\django\views\generic\base.py", line 104, in view
    return self.dispatch(request, *args, **kwargs)
           ^^^^^^^^^^^^^^^^^^^^^^^^^^^^^^^^^^^^^^^
  File "C:\Users\Archi\PycharmProjects\EPC_Map\.venv\Lib\site-packages\rest_framework\views.py", line 509, in dispatch
    response = self.handle_exception(exc)
               ^^^^^^^^^^^^^^^^^^^^^^^^^^
  File "C:\Users\Archi\PycharmProjects\EPC_Map\.venv\Lib\site-packages\rest_framework\views.py", line 469, in handle_exception
    self.raise_uncaught_exception(exc)
  File "C:\Users\Archi\PycharmProjects\EPC_Map\.venv\Lib\site-packages\rest_framework\views.py", line 480, in raise_uncaught_exception
    raise exc
  File "C:\Users\Archi\PycharmProjects\EPC_Map\.venv\Lib\site-packages\rest_framework\views.py", line 506, in dispatch
    response = handler(request, *args, **kwargs)
               ^^^^^^^^^^^^^^^^^^^^^^^^^^^^^^^^^
  File "C:\Users\Archi\PycharmProjects\EPC_Map\EPC_MAP\map\views.py", line 23, in get
    print(serializer.data)
          ^^^^^^^^^^^^^^^
  File "C:\Users\Archi\PycharmProjects\EPC_Map\.venv\Lib\site-packages\rest_framework\serializers.py", line 795, in data
    ret = super().data
          ^^^^^^^^^^^^
  File "C:\Users\Archi\PycharmProjects\EPC_Map\.venv\Lib\site-packages\rest_framework\serializers.py", line 249, in data
    self._data = self.to_representation(self.instance)
                 ^^^^^^^^^^^^^^^^^^^^^^^^^^^^^^^^^^^^^
  File "C:\Users\Archi\PycharmProjects\EPC_Map\.venv\Lib\site-packages\rest_framework\serializers.py", line 713, in to_representation
    return [
           ^
  File "C:\Users\Archi\PycharmProjects\EPC_Map\.venv\Lib\site-packages\rest_framework\serializers.py", line 714, in <listcomp>
    self.child.to_representation(item) for item in iterable
    ^^^^^^^^^^^^^^^^^^^^^^^^^^^^^^^^^^
  File "C:\Users\Archi\PycharmProjects\EPC_Map\.venv\Lib\site-packages\rest_framework\serializers.py", line 525, in to_representation
    attribute = field.get_attribute(instance)
                ^^^^^^^^^^^^^^^^^^^^^^^^^^^^^
  File "C:\Users\Archi\PycharmProjects\EPC_Map\.venv\Lib\site-packages\rest_framework\fields.py", line 470, in get_attribute
    raise type(exc)(msg)
AttributeError: Got AttributeError when attempting to get a value for field `lmk_key` on serializer `CertificateSerializer`.
The serializer field might be named incorrectly and not match any attribute or key on the `tuple` instance.
Original exception text was: 'tuple' object has no attribute 'lmk_key'.
2025-03-12 23:54:04-ERROR [log:248] Internal Server Error: /api/map/
Traceback (most recent call last):
  File "C:\Users\Archi\PycharmProjects\EPC_Map\.venv\Lib\site-packages\django\core\handlers\exception.py", line 55, in inner
    response = get_response(request)
               ^^^^^^^^^^^^^^^^^^^^^
  File "C:\Users\Archi\PycharmProjects\EPC_Map\.venv\Lib\site-packages\django\core\handlers\base.py", line 197, in _get_response
    response = wrapped_callback(request, *callback_args, **callback_kwargs)
               ^^^^^^^^^^^^^^^^^^^^^^^^^^^^^^^^^^^^^^^^^^^^^^^^^^^^^^^^^^^^
  File "C:\Users\Archi\PycharmProjects\EPC_Map\.venv\Lib\site-packages\django\views\decorators\csrf.py", line 65, in _view_wrapper
    return view_func(request, *args, **kwargs)
           ^^^^^^^^^^^^^^^^^^^^^^^^^^^^^^^^^^^
  File "C:\Users\Archi\PycharmProjects\EPC_Map\.venv\Lib\site-packages\django\views\generic\base.py", line 104, in view
    return self.dispatch(request, *args, **kwargs)
           ^^^^^^^^^^^^^^^^^^^^^^^^^^^^^^^^^^^^^^^
  File "C:\Users\Archi\PycharmProjects\EPC_Map\.venv\Lib\site-packages\rest_framework\views.py", line 509, in dispatch
    response = self.handle_exception(exc)
               ^^^^^^^^^^^^^^^^^^^^^^^^^^
  File "C:\Users\Archi\PycharmProjects\EPC_Map\.venv\Lib\site-packages\rest_framework\views.py", line 469, in handle_exception
    self.raise_uncaught_exception(exc)
  File "C:\Users\Archi\PycharmProjects\EPC_Map\.venv\Lib\site-packages\rest_framework\views.py", line 480, in raise_uncaught_exception
    raise exc
  File "C:\Users\Archi\PycharmProjects\EPC_Map\.venv\Lib\site-packages\rest_framework\views.py", line 506, in dispatch
    response = handler(request, *args, **kwargs)
               ^^^^^^^^^^^^^^^^^^^^^^^^^^^^^^^^^
  File "C:\Users\Archi\PycharmProjects\EPC_Map\EPC_MAP\map\views.py", line 25, in get
    return JsonResponse(data=serializer.data, safe=False, status=200)
                             ^^^^^^^^^^
NameError: name 'serializer' is not defined
2025-03-12 23:54:54-ERROR [log:248] Internal Server Error: /api/map/
Traceback (most recent call last):
  File "C:\Users\Archi\PycharmProjects\EPC_Map\.venv\Lib\site-packages\django\core\handlers\exception.py", line 55, in inner
    response = get_response(request)
               ^^^^^^^^^^^^^^^^^^^^^
  File "C:\Users\Archi\PycharmProjects\EPC_Map\.venv\Lib\site-packages\django\core\handlers\base.py", line 197, in _get_response
    response = wrapped_callback(request, *callback_args, **callback_kwargs)
               ^^^^^^^^^^^^^^^^^^^^^^^^^^^^^^^^^^^^^^^^^^^^^^^^^^^^^^^^^^^^
  File "C:\Users\Archi\PycharmProjects\EPC_Map\.venv\Lib\site-packages\django\views\decorators\csrf.py", line 65, in _view_wrapper
    return view_func(request, *args, **kwargs)
           ^^^^^^^^^^^^^^^^^^^^^^^^^^^^^^^^^^^
  File "C:\Users\Archi\PycharmProjects\EPC_Map\.venv\Lib\site-packages\django\views\generic\base.py", line 104, in view
    return self.dispatch(request, *args, **kwargs)
           ^^^^^^^^^^^^^^^^^^^^^^^^^^^^^^^^^^^^^^^
  File "C:\Users\Archi\PycharmProjects\EPC_Map\.venv\Lib\site-packages\rest_framework\views.py", line 509, in dispatch
    response = self.handle_exception(exc)
               ^^^^^^^^^^^^^^^^^^^^^^^^^^
  File "C:\Users\Archi\PycharmProjects\EPC_Map\.venv\Lib\site-packages\rest_framework\views.py", line 469, in handle_exception
    self.raise_uncaught_exception(exc)
  File "C:\Users\Archi\PycharmProjects\EPC_Map\.venv\Lib\site-packages\rest_framework\views.py", line 480, in raise_uncaught_exception
    raise exc
  File "C:\Users\Archi\PycharmProjects\EPC_Map\.venv\Lib\site-packages\rest_framework\views.py", line 506, in dispatch
    response = handler(request, *args, **kwargs)
               ^^^^^^^^^^^^^^^^^^^^^^^^^^^^^^^^^
  File "C:\Users\Archi\PycharmProjects\EPC_Map\EPC_MAP\map\views.py", line 21, in get
    queryset = self.get_queryset()
               ^^^^^^^^^^^^^^^^^^^
  File "C:\Users\Archi\PycharmProjects\EPC_Map\EPC_MAP\map\views.py", line 18, in get_queryset
    return Certificate.objects.values_list('pk', 'latitude', 'longitude', flat=True)
           ^^^^^^^^^^^^^^^^^^^^^^^^^^^^^^^^^^^^^^^^^^^^^^^^^^^^^^^^^^^^^^^^^^^^^^^^^
  File "C:\Users\Archi\PycharmProjects\EPC_Map\.venv\Lib\site-packages\django\db\models\manager.py", line 87, in manager_method
    return getattr(self.get_queryset(), name)(*args, **kwargs)
           ^^^^^^^^^^^^^^^^^^^^^^^^^^^^^^^^^^^^^^^^^^^^^^^^^^^
  File "C:\Users\Archi\PycharmProjects\EPC_Map\.venv\Lib\site-packages\django\db\models\query.py", line 1368, in values_list
    raise TypeError(
TypeError: 'flat' is not valid when values_list is called with more than one field.
2025-03-12 23:56:41-ERROR [log:248] Internal Server Error: /api/map/
Traceback (most recent call last):
  File "C:\Users\Archi\PycharmProjects\EPC_Map\.venv\Lib\site-packages\django\core\handlers\exception.py", line 55, in inner
    response = get_response(request)
               ^^^^^^^^^^^^^^^^^^^^^
  File "C:\Users\Archi\PycharmProjects\EPC_Map\.venv\Lib\site-packages\django\core\handlers\base.py", line 197, in _get_response
    response = wrapped_callback(request, *callback_args, **callback_kwargs)
               ^^^^^^^^^^^^^^^^^^^^^^^^^^^^^^^^^^^^^^^^^^^^^^^^^^^^^^^^^^^^
  File "C:\Users\Archi\PycharmProjects\EPC_Map\.venv\Lib\site-packages\django\views\decorators\csrf.py", line 65, in _view_wrapper
    return view_func(request, *args, **kwargs)
           ^^^^^^^^^^^^^^^^^^^^^^^^^^^^^^^^^^^
  File "C:\Users\Archi\PycharmProjects\EPC_Map\.venv\Lib\site-packages\django\views\generic\base.py", line 104, in view
    return self.dispatch(request, *args, **kwargs)
           ^^^^^^^^^^^^^^^^^^^^^^^^^^^^^^^^^^^^^^^
  File "C:\Users\Archi\PycharmProjects\EPC_Map\.venv\Lib\site-packages\rest_framework\views.py", line 511, in dispatch
    self.response = self.finalize_response(request, response, *args, **kwargs)
                    ^^^^^^^^^^^^^^^^^^^^^^^^^^^^^^^^^^^^^^^^^^^^^^^^^^^^^^^^^^
  File "C:\Users\Archi\PycharmProjects\EPC_Map\.venv\Lib\site-packages\rest_framework\views.py", line 423, in finalize_response
    assert isinstance(response, HttpResponseBase), (
           ^^^^^^^^^^^^^^^^^^^^^^^^^^^^^^^^^^^^^^
AssertionError: Expected a `Response`, `HttpResponse` or `StreamingHttpResponse` to be returned from the view, but received a `<class 'NoneType'>`
2025-03-13 00:25:16-ERROR [log:248] Internal Server Error: /api/map/565834049922010111717462241738110/
Traceback (most recent call last):
  File "C:\Users\Archi\PycharmProjects\EPC_Map\.venv\Lib\site-packages\django\core\handlers\exception.py", line 55, in inner
    response = get_response(request)
               ^^^^^^^^^^^^^^^^^^^^^
  File "C:\Users\Archi\PycharmProjects\EPC_Map\.venv\Lib\site-packages\django\core\handlers\base.py", line 197, in _get_response
    response = wrapped_callback(request, *callback_args, **callback_kwargs)
               ^^^^^^^^^^^^^^^^^^^^^^^^^^^^^^^^^^^^^^^^^^^^^^^^^^^^^^^^^^^^
  File "C:\Users\Archi\PycharmProjects\EPC_Map\.venv\Lib\site-packages\django\views\decorators\csrf.py", line 65, in _view_wrapper
    return view_func(request, *args, **kwargs)
           ^^^^^^^^^^^^^^^^^^^^^^^^^^^^^^^^^^^
  File "C:\Users\Archi\PycharmProjects\EPC_Map\.venv\Lib\site-packages\django\views\generic\base.py", line 104, in view
    return self.dispatch(request, *args, **kwargs)
           ^^^^^^^^^^^^^^^^^^^^^^^^^^^^^^^^^^^^^^^
  File "C:\Users\Archi\PycharmProjects\EPC_Map\.venv\Lib\site-packages\rest_framework\views.py", line 509, in dispatch
    response = self.handle_exception(exc)
               ^^^^^^^^^^^^^^^^^^^^^^^^^^
  File "C:\Users\Archi\PycharmProjects\EPC_Map\.venv\Lib\site-packages\rest_framework\views.py", line 469, in handle_exception
    self.raise_uncaught_exception(exc)
  File "C:\Users\Archi\PycharmProjects\EPC_Map\.venv\Lib\site-packages\rest_framework\views.py", line 480, in raise_uncaught_exception
    raise exc
  File "C:\Users\Archi\PycharmProjects\EPC_Map\.venv\Lib\site-packages\rest_framework\views.py", line 506, in dispatch
    response = handler(request, *args, **kwargs)
               ^^^^^^^^^^^^^^^^^^^^^^^^^^^^^^^^^
  File "C:\Users\Archi\PycharmProjects\EPC_Map\.venv\Lib\site-packages\rest_framework\generics.py", line 212, in get
    return self.retrieve(request, *args, **kwargs)
           ^^^^^^^^^^^^^^^^^^^^^^^^^^^^^^^^^^^^^^^
  File "C:\Users\Archi\PycharmProjects\EPC_Map\.venv\Lib\site-packages\rest_framework\mixins.py", line 54, in retrieve
    instance = self.get_object()
               ^^^^^^^^^^^^^^^^^
  File "C:\Users\Archi\PycharmProjects\EPC_Map\.venv\Lib\site-packages\rest_framework\generics.py", line 92, in get_object
    assert lookup_url_kwarg in self.kwargs, (
           ^^^^^^^^^^^^^^^^^^^^^^^^^^^^^^^
AssertionError: Expected view CertificateAPI to be called with a URL keyword argument named "pk". Fix your URL conf, or set the `.lookup_field` attribute on the view correctly.
2025-03-13 00:32:00-ERROR [log:248] Internal Server Error: /api/map/565834049922010111717462241738110/
Traceback (most recent call last):
  File "C:\Users\Archi\PycharmProjects\EPC_Map\.venv\Lib\site-packages\django\core\handlers\exception.py", line 55, in inner
    response = get_response(request)
               ^^^^^^^^^^^^^^^^^^^^^
  File "C:\Users\Archi\PycharmProjects\EPC_Map\.venv\Lib\site-packages\django\core\handlers\base.py", line 197, in _get_response
    response = wrapped_callback(request, *callback_args, **callback_kwargs)
               ^^^^^^^^^^^^^^^^^^^^^^^^^^^^^^^^^^^^^^^^^^^^^^^^^^^^^^^^^^^^
  File "C:\Users\Archi\PycharmProjects\EPC_Map\.venv\Lib\site-packages\django\views\decorators\csrf.py", line 65, in _view_wrapper
    return view_func(request, *args, **kwargs)
           ^^^^^^^^^^^^^^^^^^^^^^^^^^^^^^^^^^^
  File "C:\Users\Archi\PycharmProjects\EPC_Map\.venv\Lib\site-packages\django\views\generic\base.py", line 104, in view
    return self.dispatch(request, *args, **kwargs)
           ^^^^^^^^^^^^^^^^^^^^^^^^^^^^^^^^^^^^^^^
  File "C:\Users\Archi\PycharmProjects\EPC_Map\.venv\Lib\site-packages\rest_framework\views.py", line 509, in dispatch
    response = self.handle_exception(exc)
               ^^^^^^^^^^^^^^^^^^^^^^^^^^
  File "C:\Users\Archi\PycharmProjects\EPC_Map\.venv\Lib\site-packages\rest_framework\views.py", line 469, in handle_exception
    self.raise_uncaught_exception(exc)
  File "C:\Users\Archi\PycharmProjects\EPC_Map\.venv\Lib\site-packages\rest_framework\views.py", line 480, in raise_uncaught_exception
    raise exc
  File "C:\Users\Archi\PycharmProjects\EPC_Map\.venv\Lib\site-packages\rest_framework\views.py", line 506, in dispatch
    response = handler(request, *args, **kwargs)
               ^^^^^^^^^^^^^^^^^^^^^^^^^^^^^^^^^
  File "C:\Users\Archi\PycharmProjects\EPC_Map\EPC_MAP\map\views.py", line 25, in get
    super().get()
TypeError: RetrieveAPIView.get() missing 1 required positional argument: 'request'
2025-03-13 00:32:42-ERROR [log:248] Internal Server Error: /api/map/565834049922010111717462241738110/
Traceback (most recent call last):
  File "C:\Users\Archi\PycharmProjects\EPC_Map\.venv\Lib\site-packages\django\core\handlers\exception.py", line 55, in inner
    response = get_response(request)
               ^^^^^^^^^^^^^^^^^^^^^
  File "C:\Users\Archi\PycharmProjects\EPC_Map\.venv\Lib\site-packages\django\core\handlers\base.py", line 197, in _get_response
    response = wrapped_callback(request, *callback_args, **callback_kwargs)
               ^^^^^^^^^^^^^^^^^^^^^^^^^^^^^^^^^^^^^^^^^^^^^^^^^^^^^^^^^^^^
  File "C:\Users\Archi\PycharmProjects\EPC_Map\.venv\Lib\site-packages\django\views\decorators\csrf.py", line 65, in _view_wrapper
    return view_func(request, *args, **kwargs)
           ^^^^^^^^^^^^^^^^^^^^^^^^^^^^^^^^^^^
  File "C:\Users\Archi\PycharmProjects\EPC_Map\.venv\Lib\site-packages\django\views\generic\base.py", line 104, in view
    return self.dispatch(request, *args, **kwargs)
           ^^^^^^^^^^^^^^^^^^^^^^^^^^^^^^^^^^^^^^^
  File "C:\Users\Archi\PycharmProjects\EPC_Map\.venv\Lib\site-packages\rest_framework\views.py", line 509, in dispatch
    response = self.handle_exception(exc)
               ^^^^^^^^^^^^^^^^^^^^^^^^^^
  File "C:\Users\Archi\PycharmProjects\EPC_Map\.venv\Lib\site-packages\rest_framework\views.py", line 469, in handle_exception
    self.raise_uncaught_exception(exc)
  File "C:\Users\Archi\PycharmProjects\EPC_Map\.venv\Lib\site-packages\rest_framework\views.py", line 480, in raise_uncaught_exception
    raise exc
  File "C:\Users\Archi\PycharmProjects\EPC_Map\.venv\Lib\site-packages\rest_framework\views.py", line 506, in dispatch
    response = handler(request, *args, **kwargs)
               ^^^^^^^^^^^^^^^^^^^^^^^^^^^^^^^^^
  File "C:\Users\Archi\PycharmProjects\EPC_Map\EPC_MAP\map\views.py", line 25, in get
    super().get()
TypeError: RetrieveAPIView.get() missing 1 required positional argument: 'request'
